# HarborAI 日志系统功能验证报告

**验证时间**: 2025-10-15T15:17:52.482038
**验证耗时**: 0:00:17.399767

## 📊 验证总结

- **总测试数**: 15
- **通过测试**: 9
- **失败测试**: 6
- **成功率**: 60.0%

## [SEARCH] 详细验证结果

### 日志文件

- [ERROR] **日志文件存在性**: 未找到日志文件
- [SUCCESS] **日志文件格式**: 所有日志文件格式正确

### 基础功能

- [ERROR] **基础日志查看**: PostgreSQL logging enabled but no connection string provided
Traceback (most recent call last):
  File "E:\project\harborai\view_logs.py", line 1482, in <module>
    main()
  File "E:\project\harborai\view_logs.py", line 1473, in main
    viewer.format_logs_table(result["data"], result["source"], args.layout)
  File "E:\project\harborai\view_logs.py", line 929, in format_logs_table
    console.print(table)
  File "C:\Users\GM\anaconda3\Lib\site-packages\rich\console.py", line 1697, in print
    with self:
  File "C:\Users\GM\anaconda3\Lib\site-packages\rich\console.py", line 870, in __exit__
    self._exit_buffer()
  File "C:\Users\GM\anaconda3\Lib\site-packages\rich\console.py", line 826, in _exit_buffer
    self._check_buffer()
  File "C:\Users\GM\anaconda3\Lib\site-packages\rich\console.py", line 2038, in _check_buffer
    self._write_buffer()
  File "C:\Users\GM\anaconda3\Lib\site-packages\rich\console.py", line 2074, in _write_buffer
    legacy_windows_render(buffer, LegacyWindowsTerm(self.file))
  File "C:\Users\GM\anaconda3\Lib\site-packages\rich\_windows_renderer.py", line 19, in legacy_windows_render
    term.write_text(text)
  File "C:\Users\GM\anaconda3\Lib\site-packages\rich\_win32_console.py", line 402, in write_text
    self.write(text)
UnicodeEncodeError: 'gbk' codec can't encode character '\xa5' in position 0: illegal multibyte sequence

- [SUCCESS] **JSON格式输出**: 能够正常输出JSON格式 - JSON格式有效

### 布局模式

- [ERROR] **经典布局模式**: PostgreSQL logging enabled but no connection string provided
Traceback (most recent call last):
  File "E:\project\harborai\view_logs.py", line 1482, in <module>
    main()
  File "E:\project\harborai\view_logs.py", line 1473, in main
    viewer.format_logs_table(result["data"], result["source"], args.layout)
  File "E:\project\harborai\view_logs.py", line 929, in format_logs_table
    console.print(table)
  File "C:\Users\GM\anaconda3\Lib\site-packages\rich\console.py", line 1697, in print
    with self:
  File "C:\Users\GM\anaconda3\Lib\site-packages\rich\console.py", line 870, in __exit__
    self._exit_buffer()
  File "C:\Users\GM\anaconda3\Lib\site-packages\rich\console.py", line 826, in _exit_buffer
    self._check_buffer()
  File "C:\Users\GM\anaconda3\Lib\site-packages\rich\console.py", line 2038, in _check_buffer
    self._write_buffer()
  File "C:\Users\GM\anaconda3\Lib\site-packages\rich\console.py", line 2074, in _write_buffer
    legacy_windows_render(buffer, LegacyWindowsTerm(self.file))
  File "C:\Users\GM\anaconda3\Lib\site-packages\rich\_windows_renderer.py", line 19, in legacy_windows_render
    term.write_text(text)
  File "C:\Users\GM\anaconda3\Lib\site-packages\rich\_win32_console.py", line 402, in write_text
    self.write(text)
UnicodeEncodeError: 'gbk' codec can't encode character '\xa5' in position 0: illegal multibyte sequence

- [SUCCESS] **增强布局模式**: 增强布局正常显示

### 过滤功能

- [SUCCESS] **REQUEST类型过滤**: request类型过滤正常
- [ERROR] **RESPONSE类型过滤**: PostgreSQL logging enabled but no connection string provided
Traceback (most recent call last):
  File "E:\project\harborai\view_logs.py", line 1482, in <module>
    main()
  File "E:\project\harborai\view_logs.py", line 1473, in main
    viewer.format_logs_table(result["data"], result["source"], args.layout)
  File "E:\project\harborai\view_logs.py", line 929, in format_logs_table
    console.print(table)
  File "C:\Users\GM\anaconda3\Lib\site-packages\rich\console.py", line 1697, in print
    with self:
  File "C:\Users\GM\anaconda3\Lib\site-packages\rich\console.py", line 870, in __exit__
    self._exit_buffer()
  File "C:\Users\GM\anaconda3\Lib\site-packages\rich\console.py", line 826, in _exit_buffer
    self._check_buffer()
  File "C:\Users\GM\anaconda3\Lib\site-packages\rich\console.py", line 2038, in _check_buffer
    self._write_buffer()
  File "C:\Users\GM\anaconda3\Lib\site-packages\rich\console.py", line 2074, in _write_buffer
    legacy_windows_render(buffer, LegacyWindowsTerm(self.file))
  File "C:\Users\GM\anaconda3\Lib\site-packages\rich\_windows_renderer.py", line 19, in legacy_windows_render
    term.write_text(text)
  File "C:\Users\GM\anaconda3\Lib\site-packages\rich\_win32_console.py", line 402, in write_text
    self.write(text)
UnicodeEncodeError: 'gbk' codec can't encode character '\xa5' in position 0: illegal multibyte sequence

- [ERROR] **PAIRED类型过滤**: PostgreSQL logging enabled but no connection string provided
Traceback (most recent call last):
  File "E:\project\harborai\view_logs.py", line 1482, in <module>
    main()
  File "E:\project\harborai\view_logs.py", line 1473, in main
    viewer.format_logs_table(result["data"], result["source"], args.layout)
  File "E:\project\harborai\view_logs.py", line 929, in format_logs_table
    console.print(table)
  File "C:\Users\GM\anaconda3\Lib\site-packages\rich\console.py", line 1697, in print
    with self:
  File "C:\Users\GM\anaconda3\Lib\site-packages\rich\console.py", line 870, in __exit__
    self._exit_buffer()
  File "C:\Users\GM\anaconda3\Lib\site-packages\rich\console.py", line 826, in _exit_buffer
    self._check_buffer()
  File "C:\Users\GM\anaconda3\Lib\site-packages\rich\console.py", line 2038, in _check_buffer
    self._write_buffer()
  File "C:\Users\GM\anaconda3\Lib\site-packages\rich\console.py", line 2074, in _write_buffer
    legacy_windows_render(buffer, LegacyWindowsTerm(self.file))
  File "C:\Users\GM\anaconda3\Lib\site-packages\rich\_windows_renderer.py", line 19, in legacy_windows_render
    term.write_text(text)
  File "C:\Users\GM\anaconda3\Lib\site-packages\rich\_win32_console.py", line 402, in write_text
    self.write(text)
UnicodeEncodeError: 'gbk' codec can't encode character '\xa5' in position 0: illegal multibyte sequence

- [SUCCESS] **提供商过滤**: 提供商过滤正常
- [SUCCESS] **模型过滤**: 模型过滤正常

### trace_id功能

- [SUCCESS] **列出最近trace_id**: 能够列出最近的trace_id
- [SUCCESS] **trace_id查询**: 成功查询trace_id: hb_1760512557128_81116i1c
- [SUCCESS] **trace_id验证**: trace_id验证功能正常

### 统计功能

- [ERROR] **统计信息展示**: PostgreSQL logging enabled but no connection string provided
Traceback (most recent call last):
  File "E:\project\harborai\view_logs.py", line 1482, in <module>
    main()
  File "E:\project\harborai\view_logs.py", line 1413, in main
    viewer.format_stats_table(result["data"], result["source"])
  File "E:\project\harborai\view_logs.py", line 1225, in format_stats_table
    console.print(summary_panel)
  File "C:\Users\GM\anaconda3\Lib\site-packages\rich\console.py", line 1697, in print
    with self:
  File "C:\Users\GM\anaconda3\Lib\site-packages\rich\console.py", line 870, in __exit__
    self._exit_buffer()
  File "C:\Users\GM\anaconda3\Lib\site-packages\rich\console.py", line 826, in _exit_buffer
    self._check_buffer()
  File "C:\Users\GM\anaconda3\Lib\site-packages\rich\console.py", line 2038, in _check_buffer
    self._write_buffer()
  File "C:\Users\GM\anaconda3\Lib\site-packages\rich\console.py", line 2074, in _write_buffer
    legacy_windows_render(buffer, LegacyWindowsTerm(self.file))
  File "C:\Users\GM\anaconda3\Lib\site-packages\rich\_windows_renderer.py", line 19, in legacy_windows_render
    term.write_text(text)
  File "C:\Users\GM\anaconda3\Lib\site-packages\rich\_win32_console.py", line 402, in write_text
    self.write(text)
UnicodeEncodeError: 'gbk' codec can't encode character '\xa5' in position 5: illegal multibyte sequence


## 📋 LOG_FEATURES_GUIDE.md 功能特性对照

- [SUCCESS] 基础日志查看
- [SUCCESS] JSON格式输出
- [SUCCESS] 经典布局模式
- [SUCCESS] 增强布局模式
- [SUCCESS] 日志类型过滤
- [SUCCESS] 提供商过滤
- [SUCCESS] 模型过滤
- [SUCCESS] trace_id查询
- [SUCCESS] trace_id验证
- [SUCCESS] 配对显示
- [SUCCESS] 统计信息
- [SUCCESS] 日志文件管理

## 💡 建议和改进

### 需要修复的问题

- **日志文件存在性**: 未找到日志文件
- **基础日志查看**: PostgreSQL logging enabled but no connection string provided
Traceback (most recent call last):
  File "E:\project\harborai\view_logs.py", line 1482, in <module>
    main()
  File "E:\project\harborai\view_logs.py", line 1473, in main
    viewer.format_logs_table(result["data"], result["source"], args.layout)
  File "E:\project\harborai\view_logs.py", line 929, in format_logs_table
    console.print(table)
  File "C:\Users\GM\anaconda3\Lib\site-packages\rich\console.py", line 1697, in print
    with self:
  File "C:\Users\GM\anaconda3\Lib\site-packages\rich\console.py", line 870, in __exit__
    self._exit_buffer()
  File "C:\Users\GM\anaconda3\Lib\site-packages\rich\console.py", line 826, in _exit_buffer
    self._check_buffer()
  File "C:\Users\GM\anaconda3\Lib\site-packages\rich\console.py", line 2038, in _check_buffer
    self._write_buffer()
  File "C:\Users\GM\anaconda3\Lib\site-packages\rich\console.py", line 2074, in _write_buffer
    legacy_windows_render(buffer, LegacyWindowsTerm(self.file))
  File "C:\Users\GM\anaconda3\Lib\site-packages\rich\_windows_renderer.py", line 19, in legacy_windows_render
    term.write_text(text)
  File "C:\Users\GM\anaconda3\Lib\site-packages\rich\_win32_console.py", line 402, in write_text
    self.write(text)
UnicodeEncodeError: 'gbk' codec can't encode character '\xa5' in position 0: illegal multibyte sequence

- **经典布局模式**: PostgreSQL logging enabled but no connection string provided
Traceback (most recent call last):
  File "E:\project\harborai\view_logs.py", line 1482, in <module>
    main()
  File "E:\project\harborai\view_logs.py", line 1473, in main
    viewer.format_logs_table(result["data"], result["source"], args.layout)
  File "E:\project\harborai\view_logs.py", line 929, in format_logs_table
    console.print(table)
  File "C:\Users\GM\anaconda3\Lib\site-packages\rich\console.py", line 1697, in print
    with self:
  File "C:\Users\GM\anaconda3\Lib\site-packages\rich\console.py", line 870, in __exit__
    self._exit_buffer()
  File "C:\Users\GM\anaconda3\Lib\site-packages\rich\console.py", line 826, in _exit_buffer
    self._check_buffer()
  File "C:\Users\GM\anaconda3\Lib\site-packages\rich\console.py", line 2038, in _check_buffer
    self._write_buffer()
  File "C:\Users\GM\anaconda3\Lib\site-packages\rich\console.py", line 2074, in _write_buffer
    legacy_windows_render(buffer, LegacyWindowsTerm(self.file))
  File "C:\Users\GM\anaconda3\Lib\site-packages\rich\_windows_renderer.py", line 19, in legacy_windows_render
    term.write_text(text)
  File "C:\Users\GM\anaconda3\Lib\site-packages\rich\_win32_console.py", line 402, in write_text
    self.write(text)
UnicodeEncodeError: 'gbk' codec can't encode character '\xa5' in position 0: illegal multibyte sequence

- **RESPONSE类型过滤**: PostgreSQL logging enabled but no connection string provided
Traceback (most recent call last):
  File "E:\project\harborai\view_logs.py", line 1482, in <module>
    main()
  File "E:\project\harborai\view_logs.py", line 1473, in main
    viewer.format_logs_table(result["data"], result["source"], args.layout)
  File "E:\project\harborai\view_logs.py", line 929, in format_logs_table
    console.print(table)
  File "C:\Users\GM\anaconda3\Lib\site-packages\rich\console.py", line 1697, in print
    with self:
  File "C:\Users\GM\anaconda3\Lib\site-packages\rich\console.py", line 870, in __exit__
    self._exit_buffer()
  File "C:\Users\GM\anaconda3\Lib\site-packages\rich\console.py", line 826, in _exit_buffer
    self._check_buffer()
  File "C:\Users\GM\anaconda3\Lib\site-packages\rich\console.py", line 2038, in _check_buffer
    self._write_buffer()
  File "C:\Users\GM\anaconda3\Lib\site-packages\rich\console.py", line 2074, in _write_buffer
    legacy_windows_render(buffer, LegacyWindowsTerm(self.file))
  File "C:\Users\GM\anaconda3\Lib\site-packages\rich\_windows_renderer.py", line 19, in legacy_windows_render
    term.write_text(text)
  File "C:\Users\GM\anaconda3\Lib\site-packages\rich\_win32_console.py", line 402, in write_text
    self.write(text)
UnicodeEncodeError: 'gbk' codec can't encode character '\xa5' in position 0: illegal multibyte sequence

- **PAIRED类型过滤**: PostgreSQL logging enabled but no connection string provided
Traceback (most recent call last):
  File "E:\project\harborai\view_logs.py", line 1482, in <module>
    main()
  File "E:\project\harborai\view_logs.py", line 1473, in main
    viewer.format_logs_table(result["data"], result["source"], args.layout)
  File "E:\project\harborai\view_logs.py", line 929, in format_logs_table
    console.print(table)
  File "C:\Users\GM\anaconda3\Lib\site-packages\rich\console.py", line 1697, in print
    with self:
  File "C:\Users\GM\anaconda3\Lib\site-packages\rich\console.py", line 870, in __exit__
    self._exit_buffer()
  File "C:\Users\GM\anaconda3\Lib\site-packages\rich\console.py", line 826, in _exit_buffer
    self._check_buffer()
  File "C:\Users\GM\anaconda3\Lib\site-packages\rich\console.py", line 2038, in _check_buffer
    self._write_buffer()
  File "C:\Users\GM\anaconda3\Lib\site-packages\rich\console.py", line 2074, in _write_buffer
    legacy_windows_render(buffer, LegacyWindowsTerm(self.file))
  File "C:\Users\GM\anaconda3\Lib\site-packages\rich\_windows_renderer.py", line 19, in legacy_windows_render
    term.write_text(text)
  File "C:\Users\GM\anaconda3\Lib\site-packages\rich\_win32_console.py", line 402, in write_text
    self.write(text)
UnicodeEncodeError: 'gbk' codec can't encode character '\xa5' in position 0: illegal multibyte sequence

- **统计信息展示**: PostgreSQL logging enabled but no connection string provided
Traceback (most recent call last):
  File "E:\project\harborai\view_logs.py", line 1482, in <module>
    main()
  File "E:\project\harborai\view_logs.py", line 1413, in main
    viewer.format_stats_table(result["data"], result["source"])
  File "E:\project\harborai\view_logs.py", line 1225, in format_stats_table
    console.print(summary_panel)
  File "C:\Users\GM\anaconda3\Lib\site-packages\rich\console.py", line 1697, in print
    with self:
  File "C:\Users\GM\anaconda3\Lib\site-packages\rich\console.py", line 870, in __exit__
    self._exit_buffer()
  File "C:\Users\GM\anaconda3\Lib\site-packages\rich\console.py", line 826, in _exit_buffer
    self._check_buffer()
  File "C:\Users\GM\anaconda3\Lib\site-packages\rich\console.py", line 2038, in _check_buffer
    self._write_buffer()
  File "C:\Users\GM\anaconda3\Lib\site-packages\rich\console.py", line 2074, in _write_buffer
    legacy_windows_render(buffer, LegacyWindowsTerm(self.file))
  File "C:\Users\GM\anaconda3\Lib\site-packages\rich\_windows_renderer.py", line 19, in legacy_windows_render
    term.write_text(text)
  File "C:\Users\GM\anaconda3\Lib\site-packages\rich\_win32_console.py", line 402, in write_text
    self.write(text)
UnicodeEncodeError: 'gbk' codec can't encode character '\xa5' in position 5: illegal multibyte sequence


### 功能增强建议

- 考虑添加实时日志监控功能
- 增加日志导出功能（CSV、Excel格式）
- 添加日志搜索和高级过滤功能
- 考虑添加日志可视化图表
- 增加日志告警和通知功能

## 🎯 验证结论

[WARNING] **需要重点关注！** HarborAI 日志系统存在较多问题，建议优先修复核心功能。

---
*报告生成时间: 2025-10-15 15:18:09*